Workbook
Name AF_butter: #REF!
Name Area: [1]Resumen!$B$17:$B$26
Name Cost_Exp: #REF!
Name Dolar_Cprador_BNA: #REF!
Name Dolar_Cprador_Div: #REF!
Name Dolar_Prom_BNA: #REF!
Name Dolar_Vdor_BNA: #REF!
Name EX_CN: [2]NUMBEO!#REF!
Name EX_EU: #REF!
Name FOB_Maní: #REF!
Name GBPtoUSD: #REF!
Name PPP: '[3]Valuation factors'!$B$14
Name PPP_CI: #REF!
Name PPP_CM: #REF!
Name PPP_ID: #REF!
Name PPP_IN: #REF!
Name Pr_Flete: #REF!
Name Pr_Ind: #REF!
Name Pr_Proc_Exp: #REF!
Name Pr_Proc_Ind: #REF!
Name Pr_Prom_Alq: #REF!
Name Pr_Prom_Cosecha: #REF!

Sheet Intro
B2: Title | C2: Living Wage Global Dataset 2023/2024
B3: Author | C3: Samuel Vionnet - Valuing Impact Edgar Sacayon - Valuing Impact
B4: Citation | C4: Vionnet & Sacayon (2024) Living Wage Global Dataset. Valuing Impact
B5: Version | C5: v1.0
B6: Contact | C6: sv@valuingimpact.com
B7: Related publication | C7: Vionnet Samuel (2020) A worldwide living wage dataset for benchmarking compensation practices in global value chain - Technical paper (previous version of this dataset, published in 2020)
B8: Data reference year | C8: 2023
B9: Living wage methodology | C9: Anker & Anker 2017 The detailed methodology adaptations is provided below.
B10: Living wage type | C10: Typical family: Accounts for 1 + country employment rate working parents and uses the national fertility rate for the number of children. Standard family: Accounts for 2 adults, 2 children families. Considers 1.8 working adults. Individual person: cost of living for one single adult Single working parent typical family: accounts for 2 adults and uses the national fertility rate for the number of children. Considers only one working parent.
C11: The Numbeo data was adjusted to reflect a urban and rural living wage. Rural living wage: accounts for 20% lower food costs, 75% of rent for a 3 bedroom apartment outside the City Centre, 75% of electricity costs. Urban living wage: considers 75% of the rent for a 3 bedroom apartment in the City Centre + the total costs of food, electricity, mobile phones and internet.
B12: Coverage | C12: 218 Countries and 360 Cities
B13: Note | C13: The cost of living data was extracted from Numbeo, however it was not collected for the purpose of creating a living wage specifically. Uncertainties are high. All countries that were not covered by Numbeo were covered using a linear regresion model considering the existing living wage estimates and the purchasing power parity (PPP). This linear regresion model was re-calculated for each type of living wage. R2 is around 0.6, whcih shows an unperfect correlation. For countries: Data derived from Numbeo is indicated as "a" in the source column, and as "b" for the linear regression model (LRM). Some countries have the indication a/b wich indicates we chose the lower PPP value for the region and income level as we observed some inconsistencies. For cities: data derived from Numbeo is indicated as "a". If one of the cost data (food or housing) is missing and is replaced by an regional average, the letter "b" is indicated. If both food and housing data are missing and are replaced by regional averages, the letter "c" is used. Data is far from being perfect, specially when estimated with the linear regression model. Some effect at the edge of the distribution (such as very low income countries) makes the estimates a bit too variable on the PPP value. We recommend to use those values with care and when possible recalculate a living wages with primary data or access other datasets such as the WageIndicator Foundation, Global Living Wage Coalition or Fair Wage.
B15: Numbeo model
B16: Data source | C16: https://www.numbeo.com/cost-of-living/
B17: Food costs | C17: The food costs were estimed based on a diet combinging Numbeo prices per country leading to 2,300 kcal per day per person (for children, we assumed 70% of an adult diet). We adjusted the rate of fat, proteins, carbohydrates and other food types to follow the recommendations from the WHO. The ratio between food items are constant across countries, despite the fact that some variations might occur depending on local preferences, food availability, culture and religions. The food prices per day were then multiplied by 365 days, accounting for the number of adults and kids in the household. Most of the diet impact is based on the following food items: Loaf of Fresh White Bread Eggs Local Cheese Apples Oranges Potato Lettuce Rice Tomato Banana Onion Beef Round Chicken Breasts Milk
B18: Housing costs | C18: Housing costs consideres: housing + electricity, water and waste + internet services + mobile phone. The housing costs were provided directly by Numbeo, although for rural and urban housing/apartment costs we considered only 75% of the numbeo value as some adaptations were needed given that most of the prices communicated are average market prices which correspond to standards above basic but decent living conditions. For families we considered a 3 bedroom apartment/house, although we considered a single bedroom apartament for single individual living wage estimate. For rural utilities we used 75% of the averge utility cost of Numbeo and 75% of an internet plan (Numbeo considers 60Mo/s speed minimum with unlimited data, which is not necessary for the purpose of a basic but decent life quality).
B19: NFNH | C19: The Non Food Non Housing costs were estimated separately for adults and children. We considered the following compoenents: - Transport (monthly public transport plan for adults, to go to work and other activities) - Clothes (we considered a cost equivalent for each individual to a pair of jeans or dress, 2-3 t-shirts and some underwear) - Education (we considered the cost of education for kids only, considering 10% of the cost of a private school, given that this was the only data available in Numbeo. We considered that kids are going to public school, although there are still costs associated to public education). - Health (we considered health for all members of the family as 10% additional to the total costs of diet and housing. This is a standard estimate for households across the world, although this value can vary greatly depending on socio-economic context and personal situations).
B20: Unexpected events | C20: We considered a 5% cost over all the previous costs planned for unexpected events, according to the Anker&Anker methodology.
B21: Household data | C21: We used World Bank data to translate the cost of living into a net living wage. We considered the natality rate for 2021 and unemployment rate (to calculate the level of employment for the typical living wages). Those living wages based on typical family (statistical household composition) are not excelent at reflecting the real situation of households, as you cannot split a children in a fraction and most of the time, you either have a job or not. For this reason we tend to prefer the definition of the standard family or the single working parent typical family (as a higher bounardy for the living wage).
B22: Taxation rates | C22: We developed our own dataset of personal income tax rates for low incomes, pulling from PwC and KPMG websites on the topic. Not all countries were covered and when no information was available we assumed a 10% tax rates, which reflects an average taxation rates for low income households. Applying the taxation rates allows us to calculate a gross living wage estimates (what is currently considered a living wage).
B23: Data gaps | C23: The data from Numbeo was sorted based on the World Bank's regions and income levels. Initially, a complete dataset was created by removing any country or city that didn't have complete data. In cases where data was missing, we used the average income level and region data from the complete country-level dataset provided by the World Bank. Currency exchange rates were sourced from the World Bank and FAO.
B24: World Bank Data | C24: Price level ratio of PPP conversion factor (GDP) to market exchange rate Unemployment, total (% of total labor force) (modeled ILO estimate)
B25: World Health Organization | C25: Total fertility rate (live births per woman) 2023

Sheet LW2023
A1: No | B1: Numbeo Country name | C1: Country WB | D1: Country_Code | E1: City | F1: Region | G1: World Bank Income Level | H1: RURAL LW for a Typical family [USD/year] | I1: URBAN LW for a Typical family [USD/year] | J1: LW for a Typical familiy average [USD/year] | K1: RURAL LW for a Standard family [USD/year] | L1: URBAN LW for a Standard Family [USD/year] | M1: LW for a Standard Family average [USD/year] | N1: RURAL LW for a Single Individual [USD/year] | O1: URBAN LW for a Single Individual [USD/year] | P1: LW for a Single Individual average [USD/year] | Q1: RURAL LW for a Single working parent [USD/year] | R1: URBAN LW for a Single working parent [USD/year] | S1: LW for a Single Working Parent average [USD/year] | T1: Source
A2: 1 | B2: Aruba | C2: Aruba | D2: ABW | E2: Country | F2: Latin America & Caribbean | G2: High income | H2: 12377.365 | I2: 18885.814 | J2: 15631.589 | K2: 12750.086 | L2: 19314.95 | M2: 16032.518 | N2: 10661.764 | O2: 14060.621 | P2: 12361.193 | Q2: 24124.49 | R2: 36812.998 | S2: 30468.744 | T2: b
A3: 2 | B3: Afghanistan | C3: Afghanistan | D3: AFG | E3: Country | F3: South Asia | G3: Low income | H3: 4336.4169 | I3: 7145.9235 | J3: 5741.1702 | K3: 3979.4757 | L3: 6718.4609 | M3: 5348.9683 | N3: 2603.8651 | O3: 4462.6134 | P3: 3533.2392 | Q3: 8233.79 | R3: 13610.045 | S3: 10921.917 | T3: b
A4: 3 | B4: Angola | C4: Angola | D4: AGO | E4: Country | F4: Sub-Saharan Africa | G4: Lower middle income | H4: 8053.4072 | I4: 12572.778 | J4: 10313.093 | K4: 8033.7582 | L4: 12541.285 | M4: 10287.522 | N4: 6328.6913 | O4: 8899.3665 | P4: 7614.0289 | Q4: 15579.389 | R4: 24335.789 | S4: 19957.589 | T4: b
A5: 4 | B5: Albania | C5: Albania | D5: ALB | E5: Country | F5: Europe & Central Asia | G5: Upper middle income | H5: 6041.0066 | I5: 9992.4517 | J5: 8016.7291 | K5: 6512.7174 | L5: 10550.028 | M5: 8531.3729 | N5: 4546.4966 | O5: 7103.8613 | P5: 5825.179 | Q5: 11379.505 | R5: 18822.881 | S5: 15101.193 | T5: a
A6: 5 | B6: Andorra | C6: Andorra | D6: AND | E6: Country | F6: Europe & Central Asia | G6: High income | H6: 10174.827 | I6: 15670.079 | J6: 12922.453 | K6: 10347.682 | L6: 15864.58 | M6: 13106.131 | N6: 8454.5828 | O6: 11431.58 | P6: 9943.0815 | Q6: 19771.785 | R6: 30457.355 | S6: 25114.57 | T6: b
A7: 6 | B7: United Arab Emirates | C7: United Arab Emirates | D7: ARE | E7: Country | F7: Middle East & North Africa | G7: High income | H7: 15662.135 | I7: 27653.762 | J7: 21657.949 | K7: 16643.997 | L7: 28775.286 | M7: 22709.642 | N7: 16530.131 | O7: 24144.531 | P7: 20337.331 | Q7: 30858.948 | R7: 54485.931 | S7: 42672.44 | T7: a
A8: 7 | B8: Argentina | C8: Argentina | D8: ARG | E8: Country | F8: Latin America & Caribbean | G8: Upper middle income | H8: 6414.4503 | I8: 9467.7961 | J8: 7941.1232 | K8: 6197.1359 | L8: 9221.46 | M8: 7709.298 | N8: 3985.2828 | O8: 5753.4137 | P8: 4869.3482 | Q8: 12392.397 | R8: 18291.309 | S8: 15341.853 | T8: a
A9: 8 | B9: Armenia | C9: Armenia | D9: ARM | E9: Country | F9: Europe & Central Asia | G9: Upper middle income | H9: 12744.212 | I9: 21740.377 | J9: 17242.295 | K9: 13090.862 | L9: 22149.388 | M9: 17620.125 | N9: 11591.321 | O9: 17274.238 | P9: 14432.779 | Q9: 24393.951 | R9: 41613.691 | S9: 33003.821 | T9: a
A10: 9 | B10: American Samoa | C10: American Samoa | D10: ASM | E10: Country | F10: East Asia & Pacific | G10: High income | H10: 8909.6044 | I10: 13822.838 | J10: 11366.221 | K10: 8967.6496 | L10: 13882.555 | M10: 11425.102 | N10: 7186.6934 | O10: 9921.3587 | P10: 8554.0261 | Q10: 17271.425 | R10: 26806.431 | S10: 22038.928 | T10: b
A11: 10 | B11: Antigua and Barbuda | C11: Antigua and Barbuda | D11: ATG | E11: Country | F11: Latin America & Caribbean | G11: High income | H11: 13615.404 | I11: 20693.367 | J11: 17154.386 | K11: 14100.47 | L11: 21254.392 | M11: 17677.431 | N11: 11902.414 | O11: 15538.396 | P11: 13720.405 | Q11: 26571.131 | R11: 40385.484 | S11: 33478.307 | T11: b
A12: 11 | B12: Australia | C12: Australia | D12: AUS | E12: Country | F12: East Asia & Pacific | G12: High income | H12: 18345.299 | I12: 29073.34 | J12: 23709.319 | K12: 18816.406 | L12: 29619.759 | M12: 24218.083 | N12: 16618.971 | O12: 22645.877 | P12: 19632.424 | Q12: 36011.822 | R12: 57070.966 | S12: 46541.394 | T12: a
A13: 12 | B13: Austria | C13: Austria | D13: AUT | E13: Country | F13: Europe & Central Asia | G13: High income | H13: 14282.266 | I13: 21220.164 | J13: 17751.215 | K13: 15246.28 | L13: 22328.396 | M13: 18787.338 | N13: 11730.331 | O13: 15244.249 | P13: 13487.29 | Q13: 27851.847 | R13: 41381.441 | S13: 34616.644 | T13: a
... A219: 218 | B219: Zimbabwe | C219: Zimbabwe | D219: ZWE | E219: Country | F219: Sub-Saharan Africa | G219: Lower middle income | H219: 6722.2189 | I219: 9839.0002 | J219: 8280.6095 | K219: 5693.6016 | L219: 8593.7325 | M219: 7143.667 | N219: 4233.7053 | O219: 5756.2851 | P219: 4994.9952 | Q219: 12822.229 | R219: 18767.303 | S219: 15794.766 | T219: a
A220: 219 | B220: Alexandria, Egypt | C220: Egypt | D220: EGY | E220: Rural | F220: Middle East & North Africa | G220: Lower middle income | H220: 0 | I220: 4860.4074 | K220: 0 | L220: 4255.3229 | N220: 0 | O220: 2684.1964 | Q220: 0 | R220: 9409.8946 | T220: a
A221: 220 | B221: Rawalpindi, Pakistan | C221: Pakistan | D221: PAK | E221: Rawalpindi | F221: South Asia | G221: Lower middle income | H221: 0 | I221: 5737.6917 | K221: 0 | L221: 4881.4786 | N221: 0 | O221: 2793.4257 | Q221: 0 | R221: 11154.36 | T221: b
A222: 221 | B222: Bhopal, India | C222: India | D222: IND | E222: Bhopal | F222: South Asia | G222: Lower middle income | H222: 0 | I222: 4309.6407 | K222: 0 | L222: 4228.9445 | N222: 0 | O222: 2362.4724 | Q222: 0 | R222: 8411.4705 | T222: c
A223: 222 | B223: Karachi, Pakistan | C223: Pakistan | D223: PAK | E223: Karachi | F223: South Asia | G223: Lower middle income | H223: 0 | I223: 4509.607 | K223: 0 | L223: 3921.4634 | N223: 0 | O223: 2493.2695 | Q223: 0 | R223: 8766.9015 | T223: a
A224: 223 | B224: Bhubaneswar, India | C224: India | D224: IND | E224: Bhubaneswar | F224: South Asia | G224: Lower middle income | H224: 0 | I224: 4309.6407 | K224: 0 | L224: 4228.9445 | N224: 0 | O224: 2362.4724 | Q224: 0 | R224: 8411.4705 | T224: c
A225: 224 | B225: Indore, India | C225: India | D225: IND | E225: Indore | F225: South Asia | G225: Lower middle income | H225: 0 | I225: 4188.2981 | K225: 0 | L225: 4107.6019 | N225: 0 | O225: 2241.1298 | Q225: 0 | R225: 8174.6365 | T225: b
A226: 225 | B226: Nagpur, India | C226: India | D226: IND | E226: Nagpur | F226: South Asia | G226: Lower middle income | H226: 0 | I226: 4309.6407 | K226: 0 | L226: 4228.9445 | N226: 0 | O226: 2362.4724 | Q226: 0 | R226: 8411.4705 | T226: c
A227: 226 | B227: Coimbatore, India | C227: India | D227: IND | E227: Coimbatore | F227: South Asia | G227: Lower middle income | H227: 0 | I227: 4309.6407 | K227: 0 | L227: 4228.9445 | N227: 0 | O227: 2362.4724 | Q227: 0 | R227: 8411.4705 | T227: c
A228: 227 | B228: Dhaka, Bangladesh | C228: Bangladesh | D228: BGD | E228: Dhaka | F228: South Asia | G228: Lower middle income | H228: 0 | I228: 6051.0819 | K228: 0 | L228: 6120.4577 | N228: 0 | O228: 3684.6516 | Q228: 0 | R228: 11843.722 | T228: a
A229: 228 | B229: Lahore, Pakistan | C229: Pakistan | D229: PAK | E229: Lahore | F229: South Asia | G229: Lower middle income | H229: 0 | I229: 4988.7419 | K229: 0 | L229: 4368.5882 | N229: 0 | O229: 2864.5656 | Q229: 0 | R229: 9698.3637 | T229: a
A230: 229 | B230: Lucknow (Lakhnau), India | C230: India | D230: IND | E230: Lucknow (Lakhnau) | F230: South Asia | G230: Lower middle income | H230: 0 | I230: 4309.6407 | K230: 0 | L230: 4228.9445 | N230: 0 | O230: 2362.4724 | Q230: 0 | R230: 8411.4705 | T230: c
A231: 230 | B231: Kolkata, India | C231: India | D231: IND | E231: Kolkata | F231: South Asia | G231: Lower middle income | H231: 0 | I231: 3805.822 | K231: 0 | L231: 3746.6561 | N231: 0 | O231: 2381.3655 | Q231: 0 | R231: 7428.1272 | T231: a
... A579: 578 | B579: Brooklyn, NY, United States | C579: United States | D579: USA | E579: Brooklyn | F579: North America | G579: High income | H579: 0 | I579: 14402.341 | K579: 0 | L579: 14816.584 | N579: 0 | O579: 9568.5059 | Q579: 0 | R579: 28278.997 | T579: c

Sheet PIVOT
C3: Average of Cost of Diet [$/person per day] | D3: Column Labels
C4: Row Labels | D4: High income | E4: Low income | F4: Lower middle income | G4: Upper middle income | H4: Grand Total
C5: East Asia & Pacific | D5: 7.2223381 | F5: 4.3957042 | G5: 4.2210333 | H5: 5.6682211
C6: Europe & Central Asia | D6: 5.7419345 | F6: 2.8562444 | G6: 3.1798567 | H6: 4.7400571
C7: Latin America & Caribbean | D7: 4.4976967 | F7: 3.4570333 | G7: 3.3711133 | H7: 3.7125696
C8: Middle East & North Africa | D8: 4.4382729 | F8: 2.6191024 | G8: 3.0066583 | H8: 3.5207775
C9: North America | D9: 5.3047944 | H9: 5.3047944
C10: South Asia | F10: 2.5483533 | H10: 2.5483533
C11: Sub-Saharan Africa | E11: 0 | F11: 3.1846917 | G11: 2.2040778 | H11: 2.1433653
C12: Grand Total | D12: 5.5957984 | E12: 0 | F12: 3.0833056 | G12: 3.2623137 | H12: 4.1823227
C16: Average of NFNH Cost Adult | D16: Column Labels
C17: Row Labels | D17: High income | E17: Low income | F17: Lower middle income | G17: Upper middle income | H17: Grand Total
C18: East Asia & Pacific | D18: 255.91084 | F18: 59.773075 | G18: 155.89405 | H18: 176.93629
C19: Europe & Central Asia | D19: 238.94906 | F19: 111.1928 | G19: 167.03321 | H19: 207.84254
C20: Latin America & Caribbean | D20: 88.42624 | F20: 0 | G20: 97.75033 | H20: 83.507912
C21: Middle East & North Africa | D21: 140.66904 | F21: 102.07824 | G21: 69.5958 | H21: 116.41715
C22: North America | D22: 156.2097 | H22: 156.2097
C23: South Asia | F23: 67.63112 | H23: 67.63112
C24: Sub-Saharan Africa | E24: 0 | F24: 94.705517 | G24: 51.610333 | H24: 60.255342
C25: Grand Total | D25: 206.8656 | E25: 0 | F25: 81.244707 | G25: 129.42942 | H25: 149.57947
C29: Average of NFNH Cost Kid | D29: Column Labels
C30: Row Labels | D30: High income | E30: Low income | F30: Lower middle income | G30: Upper middle income | H30: Grand Total
C31: East Asia & Pacific | D31: 2058.5796 | F31: 558.38858 | G31: 1293.3011 | H31: 1454.4544
C32: Europe & Central Asia | D32: 1108.8325 | F32: 605.40547 | G32: 576.80456 | H32: 906.90271
C33: Latin America & Caribbean | D33: 342.94964 | F33: 0 | G33: 400.88113 | H33: 336.67997
C34: Middle East & North Africa | D34: 748.14866 | F34: 268.4611 | G34: 221.5193 | H34: 488.67386
C35: North America | D35: 1294.917 | H35: 1294.917
C36: South Asia | F36: 155.09532 | H36: 155.09532
C37: Sub-Saharan Africa | E37: 0 | F37: 266.67395 | G37: 173.93433 | H37: 176.82056
C38: Grand Total | D38: 1118.2863 | E38: 0 | F38: 307.57477 | G38: 552.90957 | H38: 734.95114
C42: Average of Housing Family URBAN (apt. 3bed.) [$/year] | D42: Column Labels
C43: Row Labels | D43: High income | E43: Low income | F43: Lower middle income | G43: Upper middle income | H43: Grand Total
C44: East Asia & Pacific | D44: 19093.618 | F44: 6308.958 | G44: 7175.793 | H44: 12506.289
C45: Europe & Central Asia | D45: 12032.908 | F45: 5267.516 | G45: 5988.7816 | H45: 9672.098
C46: Latin America & Caribbean | D46: 10234.452 | F46: 3304.68 | G46: 6214.5384 | H46: 7054.5296
C47: Middle East & North Africa | D47: 12891.3 | F47: 4410.2263 | G47: 3990.018 | H47: 8351.8835
C48: North America | D48: 12148.744 | H48: 12148.744
C49: South Asia | F49: 2894.6448 | H49: 2894.6448
C50: Sub-Saharan Africa | E50: 0 | F50: 7207.872 | G50: 3879.512 | H50: 4573.814
C51: Grand Total | D51: 12949.203 | E51: 0 | F51: 5045.9178 | G51: 5891.1427 | H51: 8706.0102
...

Sheet PPP_WB
A1: Data Source | B1: World Development Indicators
A2: Last Updated Date | B2: 45343
B3: 1 | C3: 2 | D3: 3 | E3: 4 | F3: 5 | G3: 6 | H3: 7 | I3: 8 | J3: 9 | K3: 10 | L3: 11 | M3: 12 | N3: 13 | O3: 14 | P3: 15 | Q3: 16 | R3: 17 | S3: 18 | T3: 19 | U3: 20 | V3: 21 | W3: 22 | X3: 23 | Y3: 24 | Z3: 25 | AA3: 26 | AB3: 27 | AC3: 28 | AD3: 29 | AE3: 30 | AF3: 31 | AG3: 32 | AH3: 33 | AI3: 34 | AJ3: 35 | AK3: 36 | AL3: 37 | AM3: 38 | AN3: 39 | AO3: 40 | AP3: 41 | AQ3: 42 | AR3: 43 | AS3: 44 | AT3: 45 | AU3: 46 | AV3: 47 | AW3: 48 | AX3: 49 | AY3: 50 | AZ3: 51 | BA3: 52 | BB3: 53 | BC3: 54 | BD3: 55 | BE3: 56 | BF3: 57 | BG3: 58 | BH3: 59 | BI3: 60 | BJ3: 61 | BK3: 62 | BL3: 63 | BM3: 64 | BN3: 65 | BO3: 66
A4: Country Name | B4: Country Code | C4: Indicator Name | D4: Indicator Code | E4: 1960 | F4: 1961 | G4: 1962 | H4: 1963 | I4: 1964 | J4: 1965 | K4: 1966 | L4: 1967 | M4: 1968 | N4: 1969 | O4: 1970 | P4: 1971 | Q4: 1972 | R4: 1973 | S4: 1974 | T4: 1975 | U4: 1976 | V4: 1977 | W4: 1978 | X4: 1979 | Y4: 1980 | Z4: 1981 | AA4: 1982 | AB4: 1983 | AC4: 1984 | AD4: 1985 | AE4: 1986 | AF4: 1987 | AG4: 1988 | AH4: 1989 | AI4: 1990 | AJ4: 1991 | AK4: 1992 | AL4: 1993 | AM4: 1994 | AN4: 1995 | AO4: 1996 | AP4: 1997 | AQ4: 1998 | AR4: 1999 | AS4: 2000 | AT4: 2001 | AU4: 2002 | AV4: 2003 | AW4: 2004 | AX4: 2005 | AY4: 2006 | AZ4: 2007 | BA4: 2008 | BB4: 2009 | BC4: 2010 | BD4: 2011 | BE4: 2012 | BF4: 2013 | BG4: 2014 | BH4: 2015 | BI4: 2016 | BJ4: 2017 | BK4: 2018 | BL4: 2019 | BM4: 2020 | BN4: 2021 | BO4: 2022 | BP4: Region | BQ4: Income group
A5: Aruba | B5: ABW | C5: Price level ratio of PPP conversion factor (GDP) to market exchange rate | D5: PA.NUS.PPPC.RF | AI5: 0.51589712 | AJ5: 0.52704076 | AK5: 0.53499399 | AL5: 0.55030622 | AM5: 0.57268019 | AN5: 0.57985398 | AO5: 0.58798837 | AP5: 0.59943206 | AQ5: 0.63184074 | AR5: 0.63670577 | AS5: 0.62905123 | AT5: 0.64982074 | AU5: 0.66822379 | AV5: 0.67527109 | AW5: 0.67609641 | AX5: 0.68875931 | AY5: 0.69142361 | AZ5: 0.70801446 | BA5: 0.72430159 | BB5: 0.73194703 | BC5: 0.71440666 | BD5: 0.72789978 | BE5: 0.73620188 | BF5: 0.71795586 | BG5: 0.73119708 | BH5: 0.76107146 | BI5: 0.75700816 | BJ5: 0.75457522 | BK5: 0.76248533 | BL5: 0.79469648 | BM5: 0.77762476 | BN5: 0.70705353 | BO5: 0.6830897 | BP5: =_xlfn.XLOOKUP(B5,Countries_WB!$C$2:$C$219,Countries_WB!$D$2:$D$219,"No Data",0) -> Latin America & Caribbean | BQ5: =_xlfn.XLOOKUP(B5,Countries_WB!$C$2:$C$219,Countries_WB!$E$2:$E$219,"No Data",0) -> High income
A6: Africa Eastern and Southern | B6: AFE | C6: Price level ratio of PPP conversion factor (GDP) to market exchange rate | D6: PA.NUS.PPPC.RF | BO6: =BN6 -> 0 | BP6: =_xlfn.XLOOKUP(B6,Countries_WB!$C$2:$C$219,Countries_WB!$D$2:$D$219,"No Data",0) -> No Data | BQ6: =_xlfn.XLOOKUP(B6,Countries_WB!$C$2:$C$219,Countries_WB!$E$2:$E$219,"No Data",0) -> No Data
A7: Afghanistan | B7: AFG | C7: Price level ratio of PPP conversion factor (GDP) to market exchange rate | D7: PA.NUS.PPPC.RF | AU7: 0.1931618 | AV7: 0.20568097 | AW7: 0.22826509 | AX7: 0.23623876 | AY7: 0.24446166 | AZ7: 0.29238498 | BA7: 0.28628263 | BB7: 0.28780712 | BC7: 0.31758122 | BD7: 0.3478633 | BE7: 0.33364052 | BF7: 0.30975502 | BG7: 0.29680887 | BH7: 0.26637575 | BI7: 0.25844651 | BJ7: 0.25101022 | BK7: 0.23319185 | BL7: 0.22957137 | BM7: 0.24634673 | BN7: 0.21264027 | BO7: =BN7 -> 0.21264027 | BP7: =_xlfn.XLOOKUP(B7,Countries_WB!$C$2:$C$219,Countries_WB!$D$2:$D$219,"No Data",0) -> South Asia | BQ7: =_xlfn.XLOOKUP(B7,Countries_WB!$C$2:$C$219,Countries_WB!$E$2:$E$219,"No Data",0) -> Low income
A8: Africa Western and Central | B8: AFW | C8: Price level ratio of PPP conversion factor (GDP) to market exchange rate | D8: PA.NUS.PPPC.RF | BO8: =BN8 -> 0 | BP8: =_xlfn.XLOOKUP(B8,Countries_WB!$C$2:$C$219,Countries_WB!$D$2:$D$219,"No Data",0) -> No Data | BQ8: =_xlfn.XLOOKUP(B8,Countries_WB!$C$2:$C$219,Countries_WB!$E$2:$E$219,"No Data",0) -> No Data
A9: Angola | B9: AGO | C9: Price level ratio of PPP conversion factor (GDP) to market exchange rate | D9: PA.NUS.PPPC.RF | AI9: 0.35436814 | AJ9: 0.3141862 | AK9: 0.26057401 | AL9: 0.24524466 | AM9: 0.17283246 | AN9: 0.18369947 | AO9: 0.18746716 | AP9: 0.20175839 | AQ9: 0.16154689 | AR9: 0.14743169 | AS9: 0.20756973 | AT9: 0.19067377 | AU9: 0.2306853 | AV9: 0.25596743 | AW9: 0.29706528 | AX9: 0.39306322 | AY9: 0.48429374 | AZ9: 0.51534795 | BA9: 0.61702896 | BB9: 0.4827015 | BC9: 0.54455056 | BD9: 0.68777264 | BE9: 0.68799704 | BF9: 0.66214036 | BG9: 0.61700785 | BH9: 0.44230124 | BI9: 0.25753118 | BJ9: 0.33804791 | BK9: 0.3606651 | BL9: 0.31840437 | BM9: 0.22786327 | BN9: 0.2954679 | BO9: 0.43010915 | BP9: =_xlfn.XLOOKUP(B9,Countries_WB!$C$2:$C$219,Countries_WB!$D$2:$D$219,"No Data",0) -> Sub-Saharan Africa | BQ9: =_xlfn.XLOOKUP(B9,Countries_WB!$C$2:$C$219,Countries_WB!$E$2:$E$219,"No Data",0) -> Lower middle income
A10: Albania | B10: ALB | C10: Price level ratio of PPP conversion factor (GDP) to market exchange rate | D10: PA.NUS.PPPC.RF | AI10: 0.29221517 | AJ10: 0.21279983 | AK10: 0.13296045 | AL10: 0.2154609 | AM10: 0.30909759 | AN10: 0.33944503 | AO10: 0.33887086 | AP10: 0.26396736 | AQ10: 0.26936148 | AR10: 0.29762319 | AS10: 0.29178611 | AT10: 0.29804499 | AU10: 0.30572862 | AV10: 0.36920219 | AW10: 0.43730345 | AX10: 0.45586615 | AY10: 0.45277494 | AZ10: 0.49354409 | BA10: 0.53115875 | BB10: 0.46680062 | BC10: 0.42522762 | BD10: 0.43468464 | BE10: 0.40353091 | BF10: 0.41747294 | BG10: 0.40665332 | BH10: 0.33903701 | BI10: 0.34143205 | BJ10: 0.35478921 | BK10: 0.39172937 | BL10: 0.37454545 | BM10: 0.37951951 | BN10: 0.41220218 | BO10: 0.36606802 | BP10: =_xlfn.XLOOKUP(B10,Countries_WB!$C$2:$C$219,Countries_WB!$D$2:$D$219,"No Data",0) -> Europe & Central Asia | BQ10: =_xlfn.XLOOKUP(B10,Countries_WB!$C$2:$C$219,Countries_WB!$E$2:$E$219,"No Data",0) -> Upper middle income
A11: Andorra | B11: AND | C11: Price level ratio of PPP conversion factor (GDP) to market exchange rate | D11: PA.NUS.PPPC.RF | BO11: =BN11 -> 0 | BP11: =_xlfn.XLOOKUP(B11,Countries_WB!$C$2:$C$219,Countries_WB!$D$2:$D$219,"No Data",0) -> Europe & Central Asia | BQ11: =_xlfn.XLOOKUP(B11,Countries_WB!$C$2:$C$219,Countries_WB!$E$2:$E$219,"No Data",0) -> High income
A12: Arab World | B12: ARB | C12: Price level ratio of PPP conversion factor (GDP) to market exchange rate | D12: PA.NUS.PPPC.RF | BO12: =BN12 -> 0 | BP12: =_xlfn.XLOOKUP(B12,Countries_WB!$C$2:$C$219,Countries_WB!$D$2:$D$219,"No Data",0) -> No Data | BQ12: =_xlfn.XLOOKUP(B12,Countries_WB!$C$2:$C$219,Countries_WB!$E$2:$E$219,"No Data",0) -> No Data
A13: United Arab Emirates | B13: ARE | C13: Price level ratio of PPP conversion factor (GDP) to market exchange rate | D13: PA.NUS.PPPC.RF | AI13: 0.30721963 | AJ13: 0.29957965 | AK13: 0.29819689 | AL13: 0.2950151 | AM13: 0.28808884 | AN13: 0.29319779 | AO13: 0.30454805 | AP13: 0.2965343 | AQ13: 0.28064371 | AR13: 0.30011027 | AS13: 0.32709111 | AT13: 0.3123692 | AU13: 0.31917372 | AV13: 0.32574291 | AW13: 0.34419606 | AX13: 0.38888424 | AY13: 0.42237056 | AZ13: 0.46280294 | BA13: 0.53825252 | BB13: 0.45362224 | BC13: 0.52231922 | BD13: 0.57906287 | BE13: 0.59298151 | BF13: 0.60267283 | BG13: 0.5943001 | BH13: 0.59572081 | BI13: 0.59625653 | BJ13: 0.6049808 | BK13: 0.63766672 | BL13: 0.60641831 | BM13: 0.52658678 | BN13: 0.57371062 | BO13: 0.60694538 | BP13: =_xlfn.XLOOKUP(B13,Countries_WB!$C$2:$C$219,Countries_WB!$D$2:$D$219,"No Data",0) -> Middle East & North Africa | BQ13: =_xlfn.XLOOKUP(B13,Countries_WB!$C$2:$C$219,Countries_WB!$E$2:$E$219,"No Data",0) -> High income
A14: Argentina | B14: ARG | C14: Price level ratio of PPP conversion factor (GDP) to market exchange rate | D14: PA.NUS.PPPC.RF | AI14: 0.60289798 | AJ14: 0.71722015 | AK14: 0.78342566 | AL14: 0.73185857 | AM14: 0.73623721 | AN14: 0.74394034 | AO14: 0.73018131 | AP14: 0.7144733 | AQ14: 0.69447301 | AR14: 0.67224511 | AS14: 0.66417111 | AT14: 0.64241992 | AU14: 0.25818847 | AV14: 0.30372284 | AW14: 0.35011035 | AX14: 0.37640609 | AY14: 0.39545434 | AZ14: 0.43672924 | BA14: 0.51782555 | BB14: 0.50366313 | BC14: 0.57495647 | BD14: 0.66497196 | BE14: 0.66607756 | BF14: 0.64973487 | BG14: 0.62664811 | BH14: 0.68584551 | BI14: 0.6298181 | BJ14: 0.61927206 | BK14: 0.50635841 | BL14: 0.43305567 | BM14: 0.40873882 | BN14: 0.44686788 | BO14: 0.5145284 | BP14: =_xlfn.XLOOKUP(B14,Countries_WB!$C$2:$C$219,Countries_WB!$D$2:$D$219,"No Data",0) -> Latin America & Caribbean | BQ14: =_xlfn.XLOOKUP(B14,Countries_WB!$C$2:$C$219,Countries_WB!$E$2:$E$219,"No Data",0) -> Upper middle income
A15: Armenia | B15: ARM | C15: Price level ratio of PPP conversion factor (GDP) to market exchange rate | D15: PA.NUS.PPPC.RF | AI15: 0.2302015 | AJ15: 0.23128173 | AK15: 0.23892492 | AL15: 0.24153291 | AM15: 0.24562995 | AN15: 0.25126551 | AO15: 0.25349854 | AP15: 0.24761344 | AQ15: 0.26358548 | AR15: 0.24520893 | AS15: 0.2345254 | AT15: 0.23191914 | AU15: 0.22628697 | AV15: 0.2299382 | AW15: 0.25820504 | AX15: 0.30115974 | AY15: 0.33623157 | AZ15: 0.41520106 | BA15: 0.48274692 | BB15: 0.41408507 | BC15: 0.42870874 | BD15: 0.43932784 | BE15: 0.39317571 | BF15: 0.39022474 | BG15: 0.39715806 | BH15: 0.36182653 | BI15: 0.33555225 | BJ15: 0.32311043 | BK15: 0.3241386 | BL15: 0.32352275 | BM15: 0.31943117 | BN15: 0.31721607 | BO15: 0.37003861 | BP15: =_xlfn.XLOOKUP(B15,Countries_WB!$C$2:$C$219,Countries_WB!$D$2:$D$219,"No Data",0) -> Europe & Central Asia | BQ15: =_xlfn.XLOOKUP(B15,Countries_WB!$C$2:$C$219,Countries_WB!$E$2:$E$219,"No Data",0) -> Upper middle income
A16: American Samoa | B16: ASM | C16: Price level ratio of PPP conversion factor (GDP) to market exchange rate | D16: PA.NUS.PPPC.RF | BO16: =BN16 -> 0 | BP16: =_xlfn.XLOOKUP(B16,Countries_WB!$C$2:$C$219,Countries_WB!$D$2:$D$219,"No Data",0) -> East Asia & Pacific | BQ16: =_xlfn.XLOOKUP(B16,Countries_WB!$C$2:$C$219,Countries_WB!$E$2:$E$219,"No Data",0) -> High income
A17: Antigua and Barbuda | B17: ATG | C17: Price level ratio of PPP conversion factor (GDP) to market exchange rate | D17: PA.NUS.PPPC.RF | AI17: 0.6520796 | AJ17: 0.64718903 | AK17: 0.64834313 | AL17: 0.64481481 | AM17: 0.65181733 | AN17: 0.65377388 | AO17: 0.6611328 | AP17: 0.6618013 | AQ17: 0.66824339 | AR17: 0.66886928 | AS17: 0.64623768 | AT17: 0.64136898 | AU17: 0.63595851 | AV17: 0.61825632 | AW17: 0.61136301 | AX17: 0.61922212 | AY17: 0.60313627 | AZ17: 0.60919452 | BA17: 0.62391504 | BB17: 0.63132942 | BC17: 0.63302354 | BD17: 0.62643581 | BE17: 0.67724864 | BF17: 0.68682026 | BG17: 0.70915372 | BH17: 0.75538565 | BI17: 0.76297892 | BJ17: 0.77537077 | BK17: 0.76822486 | BL17: 0.76010837 | BM17: 0.75632045 | BN17: 0.75936743 | BO17: 0.75552332 | BP17: =_xlfn.XLOOKUP(B17,Countries_WB!$C$2:$C$219,Countries_WB!$D$2:$D$219,"No Data",0) -> Latin America & Caribbean | BQ17: =_xlfn.XLOOKUP(B17,Countries_WB!$C$2:$C$219,Countries_WB!$E$2:$E$219,"No Data",0) -> High income
A18: Australia | B18: AUS | C18: Price level ratio of PPP conversion factor (GDP) to market exchange rate | D18: PA.NUS.PPPC.RF | AI18: 1.0499433 | AJ18: 1.0574168 | AK18: 1.0202815 | AL18: 0.92108628 | AM18: 0.89880664 | AN18: 0.9719305 | AO18: 0.99501138 | AP18: 1.0225583 | AQ18: 0.88107712 | AR18: 0.81272716 | AS18: 0.82400316 | AT18: 0.71243028 | AU18: 0.6992801 | AV18: 0.78740711 | AW18: 0.97081448 | AX18: 1.0436844 | AY18: 1.050191 | AZ18: 1.1199812 | BA18: 1.3242023 | BB18: 1.0621192 | BC18: 1.3243821 | BD18: 1.4898029 | BE18: 1.5881371 | BF18: 1.4846383 | BG18: 1.3334554 | BH18: 1.2261028 | BI18: 1.0556047 | BJ18: 1.1143362 | BK18: 1.1397413 | BL18: 1.0584112 | BM18: 0.97466534 | BN18: 1.0803877 | BO18: 1.0297977 | BP18: =_xlfn.XLOOKUP(B18,Countries_WB!$C$2:$C$219,Countries_WB!$D$2:$D$219,"No Data",0) -> East Asia & Pacific | BQ18: =_xlfn.XLOOKUP(B18,Countries_WB!$C$2:$C$219,Countries_WB!$E$2:$E$219,"No Data",0) -> High income
A19: Austria | B19: AUT | C19: Price level ratio of PPP conversion factor (GDP) to market exchange rate | D19: PA.NUS.PPPC.RF | AI19: 1.1133825 | AJ19: 1.0869806 | AK19: 1.1684523 | AL19: 1.1080693 | AM19: 1.1326623 | AN19: 1.2796738 | AO19: 1.2136938 | AP19: 1.0502943 | AQ19: 1.0257248 | AR19: 0.98467725 | AS19: 0.83812759 | AT19: 0.82665799 | AU19: 0.8508244 | AV19: 1.0046096 | AW19: 1.092237 | AX19: 1.0972117 | AY19: 1.0799154 | AZ19: 1.1896695 | BA19: 1.2566488 | BB19: 1.17681 | BC19: 1.1165623 | BD19: 1.1572354 | BE19: 1.0453657 | BF19: 1.0586177 | BG19: 1.0612024 | BH19: 0.88629332 | BI19: 0.85998734 | BJ19: 0.87551308 | BK19: 0.90390612 | BL19: 0.8386409 | BM19: 0.85243352 | BN19: 0.89451596 | BO19: 0.76736286 | BP19: =_xlfn.XLOOKUP(B19,Countries_WB!$C$2:$C$219,Countries_WB!$D$2:$D$219,"No Data",0) -> Europe & Central Asia | BQ19: =_xlfn.XLOOKUP(B19,Countries_WB!$C$2:$C$219,Countries_WB!$E$2:$E$219,"No Data",0) -> High income
A20: Azerbaijan | B20: AZE | C20: Price level ratio of PPP conversion factor (GDP) to market exchange rate | D20: PA.NUS.PPPC.RF | AI20: 0.23570657 | AJ20: 0.1381004 | AK20: 0.014515373 | AL20: 0.06511922 | AM20: 0.060325485 | AN20: 0.1357263 | AO20: 0.17289738 | AP20: 0.20039266 | AQ20: 0.20215271 | AR20: 0.19123887 | AS20: 0.19372026 | AT20: 0.18660795 | AU20: 0.18344226 | AV20: 0.19045943 | AW20: 0.20252754 | AX20: 0.2341644 | AY20: 0.2675348 | AZ20: 0.32825213 | BA20: 0.42982358 | BB20: 0.3542935 | BC20: 0.39809414 | BD20: 0.48564845 | BE20: 0.46973288 | BF20: 0.45816338 | BG20: 0.45235584 | BH20: 0.36821234 | BI20: 0.27003542 | BJ20: 0.29368165 | BK20: 0.32573219 | BL20: 0.31922279 | BM20: 0.29180538 | BN20: 0.33954756 | BO20: 0.43537183 | BP20: =_xlfn.XLOOKUP(B20,Countries_WB!$C$2:$C$219,Countries_WB!$D$2:$D$219,"No Data",0) -> Europe & Central Asia | BQ20: =_xlfn.XLOOKUP(B20,Countries_WB!$C$2:$C$219,Countries_WB!$E$2:$E$219,"No Data",0) -> Upper middle income
A21: Burundi | B21: BDI | C21: Price level ratio of PPP conversion factor (GDP) to market exchange rate | D21: PA.NUS.PPPC.RF | AI21: 0.41590998 | AJ21: 0.39510548 | AK21: 0.3548028 | AL21: 0.3203667 | AM21: 0.321434 | AN21: 0.36978037 | AO21: 0.34286791 | AP21: 0.38343538 | AQ21: 0.33253466 | AR21: 0.29949863 | AS21: 0.25919966 | AT21: 0.25018251 | AU21: 0.22202927 | AV21: 0.20954953 | AW21: 0.22706293 | AX21: 0.26631734 | AY21: 0.27935936 | AZ21: 0.28003391 | BA21: 0.31141557 | BB21: 0.32943442 | BC21: 0.35322867 | BD21: 0.36596533 | BE21: 0.36537326 | BF21: 0.3468036 | BG21: 0.35372362 | BH21: 0.36303819 | BI21: 0.31638869 | BJ21: 0.32518573 | BK21: 0.30604802 | BL21: 0.28526399 | BM21: 0.28864105 | BN21: 0.28067749 | BO21: 0.30966647 | BP21: =_xlfn.XLOOKUP(B21,Countries_WB!$C$2:$C$219,Countries_WB!$D$2:$D$219,"No Data",0) -> Sub-Saharan Africa | BQ21: =_xlfn.XLOOKUP(B21,Countries_WB!$C$2:$C$219,Countries_WB!$E$2:$E$219,"No Data",0) -> Low income
A22: Belgium | B22: BEL | C22: Price level ratio of PPP conversion factor (GDP) to market exchange rate | D22: PA.NUS.PPPC.RF | AI22: 1.1022936 | AJ22: 1.0734542 | AK22: 1.1528946 | AL22: 1.088413 | AM22: 1.1249674 | AN22: 1.2657923 | AO22: 1.2086137 | AP22: 1.0458751 | AQ22: 1.0397611 | AR22: 0.99260876 | AS22: 0.83119588 | AT22: 0.79931174 | AU22: 0.82576953 | AV22: 0.99097342 | AW22: 1.1049845 | AX22: 1.1094648 | AY22: 1.0978014 | AZ22: 1.2044611 | BA22: 1.2750567 | BB22: 1.1857059 | BC22: 1.1091144 | BD22: 1.1579829 | BE22: 1.0562723 | BF22: 1.0706836 | BG22: 1.0630849 | BH22: 0.88760809 | BI22: 0.86450351 | BJ22: 0.87621913 | BK22: 0.9050918 | BL22: 0.83580079 | BM22: 0.83412069 | BN22: 0.87130823 | BO22: 0.76249251 | BP22: =_xlfn.XLOOKUP(B22,Countries_WB!$C$2:$C$219,Countries_WB!$D$2:$D$219,"No Data",0) -> Europe & Central Asia | BQ22: =_xlfn.XLOOKUP(B22,Countries_WB!$C$2:$C$219,Countries_WB!$E$2:$E$219,"No Data",0) -> High income
A23: Benin | B23: BEN | C23: Price level ratio of PPP conversion factor (GDP) to market exchange rate | D23: PA.NUS.PPPC.RF | AI23: 0.43251856 | AJ23: 0.40682925 | AK23: 0.32971804 | AL23: 0.40830152 | AM23: 0.27219587 | AN23: 0.34132307 | AO23: 0.3496493 | AP23: 0.31230095 | AQ23: 0.3215208 | AR23: 0.32986915 | AS23: 0.29166968 | AT23: 0.282051 | AU23: 0.30363092 | AV23: 0.36709998 | AW23: 0.39616121 | AX23: 0.40066919 | AY23: 0.40048716 | AZ23: 0.42728708 | BA23: 0.47887102 | BB23: 0.46270246 | BC23: 0.43839616 | BD23: 0.46776493 | BE23: 0.45833178 | BF23: 0.4686726 | BG23: 0.45577903 | BH23: 0.37300327 | BI23: 0.3618492 | BJ23: 0.37332487 | BK23: 0.38366221 | BL23: 0.35585919 | BM23: 0.36872009 | BN23: 0.37130683 | BO23: 0.32110081 | BP23: =_xlfn.XLOOKUP(B23,Countries_WB!$C$2:$C$219,Countries_WB!$D$2:$D$219,"No Data",0) -> Sub-Saharan Africa | BQ23: =_xlfn.XLOOKUP(B23,Countries_WB!$C$2:$C$219,Countries_WB!$E$2:$E$219,"No Data",0) -> Lower middle income
A24: Burkina Faso | B24: BFA | C24: Price level ratio of PPP conversion factor (GDP) to market exchange rate | D24: PA.NUS.PPPC.RF | AI24: 0.59728072 | AJ24: 0.53546278 | AK24: 0.55924411 | AL24: 0.50329717 | AM24: 0.28811314 | AN24: 0.33513627 | AO24: 0.32224997 | AP24: 0.28196636 | AQ24: 0.29776288 | AR24: 0.33039576 | AS24: 0.27768596 | AT24: 0.27377224 | AU24: 0.29330362 | AV24: 0.34918788 | AW24: 0.37429175 | AX24: 0.37653903 | AY24: 0.36620382 | AZ24: 0.39889112 | BA24: 0.4584953 | BB24: 0.44243496 | BC24: 0.43123853 | BD24: 0.47345669 | BE24: 0.46807499 | BF24: 0.46786684 | BG24: 0.46850125 | BH24: 0.38127785 | BI24: 0.36313643 | BJ24: 0.35951912 | BK24: 0.37095515 | BL24: 0.34856747 | BM24: 0.37322027 | BN24: 0.37013605 | BO24: 0.32551306 | BP24: =_xlfn.XLOOKUP(B24,Countries_WB!$C$2:$C$219,Countries_WB!$D$2:$D$219,"No Data",0) -> Sub-Saharan Africa | BQ24: =_xlfn.XLOOKUP(B24,Countries_WB!$C$2:$C$219,Countries_WB!$E$2:$E$219,"No Data",0) -> Low income
A25: Bangladesh | B25: BGD | C25: Price level ratio of PPP conversion factor (GDP) to market exchange rate | D25: PA.NUS.PPPC.RF | AI25: 0.41206133 | AJ25: 0.37734705 | AK25: 0.3583881 | AL25: 0.34970663 | AM25: 0.33555764 | AN25: 0.35127283 | AO25: 0.35341008 | AP25: 0.34541995 | AQ25: 0.33647708 | AR25: 0.32515272 | AS25: 0.31432915 | AT25: 0.2959567 | AU25: 0.28446617 | AV25: 0.29278829 | AW25: 0.29322985 | AX25: 0.28463782 | AY25: 0.26770493 | AZ25: 0.26989308 | BA25: 0.28750447 | BB25: 0.30414446 | BC25: 0.32023192 | BD25: 0.32881233 | BE25: 0.3006226 | BF25: 0.31233805 | BG25: 0.33220161 | BH25: 0.35113227 | BI25: 0.36414154 | BJ25: 0.37584234 | BK25: 0.37414762 | BL25: 0.37235468 | BM25: 0.37823362 | BN25: 0.3768345 | BO25: 0.36340505 | BP25: =_xlfn.XLOOKUP(B25,Countries_WB!$C$2:$C$219,Countries_WB!$D$2:$D$219,"No Data",0) -> South Asia | BQ25: =_xlfn.XLOOKUP(B25,Countries_WB!$C$2:$C$219,Countries_WB!$E$2:$E$219,"No Data",0) -> Lower middle income
A26: Bulgaria | B26: BGR | C26: Price level ratio of PPP conversion factor (GDP) to market exchange rate | D26: PA.NUS.PPPC.RF | AI26: 0.31340214 | AJ26: 0.17562752 | AK26: 0.1751464 | AL26: 0.18174099 | AM26: 0.15645762 | AN26: 0.29176416 | AO26: 0.21465819 | AP26: 0.23674578 | AQ26: 0.29466916 | AR26: 0.28577447 | AS26: 0.25242166 | AT26: 0.25443762 | AU26: 0.26879814 | AV26: 0.32308065 | AW26: 0.36838159 | AX26: 0.3789394 | AY26: 0.39654265 | AZ26: 0.45931616 | BA26: 0.506823 | BB26: 0.49276043 | BC26: 0.45885427 | BD26: 0.49895036 | BE26: 0.45511599 | BF26: 0.46174528 | BG26: 0.44914286 | BH26: 0.38501126 | BI26: 0.37731128 | BJ26: 0.39061712 | BK26: 0.41065907 | BL26: 0.39247851 | BM26: 0.40436952 | BN26: 0.43679234 | BO26: 0.4128885 | BP26: =_xlfn.XLOOKUP(B26,Countries_WB!$C$2:$C$219,Countries_WB!$D$2:$D$219,"No Data",0) -> Europe & Central Asia | BQ26: =_xlfn.XLOOKUP(B26,Countries_WB!$C$2:$C$219,Countries_WB!$E$2:$E$219,"No Data",0) -> Upper middle income
A27: Bahrain | B27: BHR | C27: Price level ratio of PPP conversion factor (GDP) to market exchange rate | D27: PA.NUS.PPPC.RF | AI27: 0.31770024 | AJ27: 0.30152267 | AK27: 0.28438994 | AL27: 0.26939915 | AM27: 0.28310384 | AN27: 0.28031367 | AO27: 0.27581502 | AP27: 0.27366566 | AQ27: 0.251521 | AR27: 0.25461437 | AS27: 0.32364416 | AT27: 0.30586631 | AU27: 0.31145552 | AV27: 0.33170226 | AW27: 0.35853538 | AX27: 0.39538163 | AY27: 0.41746187 | AZ27: 0.44076561 | BA27: 0.48162184 | BB27: 0.41637143 | BC27: 0.44204173 | BD27: 0.47520877 | BE27: 0.46678006 | BF27: 0.48052393 | BG27: 0.48901117 | BH27: 0.49662527 | BI27: 0.50500273 | BJ27: 0.49765349 | BK27: 0.50715908 | BL27: 0.49863617 | BM27: 0.46235026 | BN27: 0.48905763 | BO27: 0.49220932 | BP27: =_xlfn.XLOOKUP(B27,Countries_WB!$C$2:$C$219,Countries_WB!$D$2:$D$219,"No Data",0) -> Middle East & North Africa | BQ27: =_xlfn.XLOOKUP(B27,Countries_WB!$C$2:$C$219,Countries_WB!$E$2:$E$219,"No Data",0) -> High income
A28: Bahamas, The | B28: BHS | C28: Price level ratio of PPP conversion factor (GDP) to market exchange rate | D28: PA.NUS.PPPC.RF | AI28: 0.98157575 | AJ28: 0.97374055 | AK28: 0.98922702 | AL28: 0.95808901 | AM28: 0.95853874 | AN28: 0.94638563 | AO28: 0.93851643 | AP28: 0.94039157 | AQ28: 0.95828023 | AR28: 0.99174806 | AS28: 0.9787255 | AT28: 0.96054134 | AU28: 0.98325893 | AV28: 0.97536459 | AW28: 0.96121718 | AX28: 0.97911314 | AY28: 0.95767233 | AZ28: 0.95996098 | BA28: 0.95591721 | BB28: 0.93998539 | BC28: 0.92517664 | BD28: 0.89856344 | BE28: 0.91523546 | BF28: 0.90308458 | BG28: 0.90426666 | BH28: 0.93631327 | BI28: 0.92412019 | BJ28: 0.90140676 | BK28: 0.88321199 | BL28: 0.9021332 | BM28: 0.86962946 | BN28: 0.8407155 | BO28: 0.768348 | BP28: =_xlfn.XLOOKUP(B28,Countries_WB!$C$2:$C$219,Countries_WB!$D$2:$D$219,"No Data",0) -> Latin America & Caribbean | BQ28: =_xlfn.XLOOKUP(B28,Countries_WB!$C$2:$C$219,Countries_WB!$E$2:$E$219,"No Data",0) -> High income
A29: Bosnia and Herzegovina | B29: BIH | C29: Price level ratio of PPP conversion factor (GDP) to market exchange rate | D29: PA.NUS.PPPC.RF | AM29: 0.40714414 | AN29: 0.4906732 | AO29: 0.38061961 | AP29: 0.36694766 | AQ29: 0.35192534 | AR29: 0.36043875 | AS29: 0.32275364 | AT29: 0.32227641 | AU29: 0.34440548 | AV29: 0.41358777 | AW29: 0.45352474 | AX29: 0.45998804 | AY29: 0.46089358 | AZ29: 0.51154826 | BA29: 0.56385694 | BB29: 0.52217013 | BC29: 0.49586183 | BD29: 0.51044364 | BE29: 0.46376489 | BF29: 0.4658091 | BG29: 0.46616337 | BH29: 0.39358852 | BI29: 0.38208179 | BJ29: 0.39223145 | BK29: 0.40702398 | BL29: 0.37811971 | BM29: 0.38402565 | BN29: 0.41351095 | BO29: 0.37861383 | BP29: =_xlfn.XLOOKUP(B29,Countries_WB!$C$2:$C$219,Countries_WB!$D$2:$D$219,"No Data",0) -> Europe & Central Asia | BQ29: =_xlfn.XLOOKUP(B29,Countries_WB!$C$2:$C$219,Countries_WB!$E$2:$E$219,"No Data",0) -> Upper middle income
A30: Belarus | B30: BLR | C30: Price level ratio of PPP conversion factor (GDP) to market exchange rate | D30: PA.NUS.PPPC.RF | AK30: 0.18293846 | AL30: 0.34510882 | AM30: 0.34852683 | AN30: 0.35597793 | AO30: 0.35919806 | AP30: 0.30352195 | AQ30: 0.2982587 | AR30: 0.22682853 | AS30: 0.21998166 | AT30: 0.19926717 | AU30: 0.22065185 | AV30: 0.246888 | AW30: 0.28007142 | AX30: 0.32404193 | AY30: 0.3496333 | AZ30: 0.38398378 | BA30: 0.45875069 | BB30: 0.38094451 | BC30: 0.39283589 | BD30: 0.39410614 | BE30: 0.3840434 | BF30: 0.42108035 | BG30: 0.43883056 | BH30: 0.32975057 | BI30: 0.28335723 | BJ30: 0.31518376 | BK30: 0.32731629 | BL30: 0.34008479 | BM30: 0.32203523 | BN30: 0.34154892 | BO30: 0.3498022 | BP30: =_xlfn.XLOOKUP(B30,Countries_WB!$C$2:$C$219,Countries_WB!$D$2:$D$219,"No Data",0) -> Europe & Central Asia | BQ30: =_xlfn.XLOOKUP(B30,Countries_WB!$C$2:$C$219,Countries_WB!$E$2:$E$219,"No Data",0) -> Upper middle income
A31: Belize | B31: BLZ | C31: Price level ratio of PPP conversion factor (GDP) to market exchange rate | D31: PA.NUS.PPPC.RF | AI31: 0.66998017 | AJ31: 0.63214262 | AK31: 0.63913283 | AL31: 0.63605378 | AM31: 0.63918286 | AN31: 0.65933441 | AO31: 0.66527493 | AP31: 0.64418684 | AQ31: 0.65235645 | AR31: 0.63253314 | AS31: 0.62726675 | AT31: 0.60145256 | AU31: 0.59648606 | AV31: 0.56062537 | AW31: 0.55739561 | AX31: 0.5567275 | AY31: 0.55760112 | AZ31: 0.56375555 | BA31: 0.57260384 | BB31: 0.55488506 | BC31: 0.56013156 | BD31: 0.57561415 | BE31: 0.61951077 | BF31: 0.63214421 | BG31: 0.65624201 | BH31: 0.65926254 | BI31: 0.67113715 | BJ31: 0.68753254 | BK31: 0.67203545 | BL31: 0.65932945 | BM31: 0.64725923 | BN31: 0.62227147 | BO31: 0.62415566 | BP31: =_xlfn.XLOOKUP(B31,Countries_WB!$C$2:$C$219,Countries_WB!$D$2:$D$219,"No Data",0) -> Latin America & Caribbean | BQ31: =_xlfn.XLOOKUP(B31,Countries_WB!$C$2:$C$219,Countries_WB!$E$2:$E$219,"No Data",0) -> Upper middle income
A32: Bermuda | B32: BMU | C32: Price level ratio of PPP conversion factor (GDP) to market exchange rate | D32: PA.NUS.PPPC.RF | AI32: 0.87348347 | AJ32: 0.89924336 | AK32: 0.90394686 | AL32: 0.92890059 | AM32: 0.92730122 | AN32: 0.94620714 | AO32: 1.2020489 | AP32: 1.2292211 | AQ32: 1.2488644 | AR32: 1.26491 | AS32: 1.1844887 | AT32: 1.1425301 | AU32: 1.2215264 | AV32: 1.2317221 | AW32: 1.2558053 | AX32: 1.299963 | AY32: 1.3288615 | AZ32: 1.3789658 | BA32: 1.4221403 | BB32: 1.4278297 | BC32: 1.4424243 | BD32: 1.3967968 | BE32: 1.4592482 | BF32: 1.4417595 | BG32: 1.4317273 | BH32: 1.4192437 | BI32: 1.3997251 | BJ32: 1.3664159 | BK32: 1.3558353 | BL32: 1.3641656 | BM32: 1.3410046 | BN32: 1.289223 | BO32: 1.2389309 | BP32: =_xlfn.XLOOKUP(B32,Countries_WB!$C$2:$C$219,Countries_WB!$D$2:$D$219,"No Data",0) -> North America | BQ32: =_xlfn.XLOOKUP(B32,Countries_WB!$C$2:$C$219,Countries_WB!$E$2:$E$219,"No Data",0) -> High income
A33: Bolivia | B33: BOL | C33: Price level ratio of PPP conversion factor (GDP) to market exchange rate | D33: PA.NUS.PPPC.RF | AI33: 0.29892102 | AJ33: 0.30151951 | AK33: 0.30634254 | AL33: 0.29161541 | AM33: 0.28451327 | AN33: 0.29888209 | AO33: 0.30979651 | AP33: 0.31091266 | AQ33: 0.31384711 | AR33: 0.30046621 | AS33: 0.29052388 | AT33: 0.27088886 | AU33: 0.25271745 | AV33: 0.24668394 | AW33: 0.25032841 | AX33: 0.25299034 | AY33: 0.28084656 | AZ33: 0.29961679 | BA33: 0.35197455 | BB33: 0.3518832 | BC33: 0.37840397 | BD33: 0.42971433 | BE33: 0.44073544 | BF33: 0.4389865 | BG33: 0.43672294 | BH33: 0.4255713 | BI33: 0.41023329 | BJ33: 0.39782107 | BK33: 0.40035477 | BL33: 0.39057368 | BM33: 0.37839323 | BN33: 0.37644982 | BO33: 0.36971056 | BP33: =_xlfn.XLOOKUP(B33,Countries_WB!$C$2:$C$219,Countries_WB!$D$2:$D$219,"No Data",0) -> Latin America & Caribbean | BQ33: =_xlfn.XLOOKUP(B33,Countries_WB!$C$2:$C$219,Countries_WB!$E$2:$E$219,"No Data",0) -> Lower middle income
A34: Brazil | B34: BRA | C34: Price level ratio of PPP conversion factor (GDP) to market exchange rate | D34: PA.NUS.PPPC.RF | AI34: 0.46317135 | AJ34: 0.39101741 | AK34: 0.36859218 | AL34: 0.38507596 | AM34: 0.44388355 | AN34: 0.58752812 | AO34: 0.62399712 | AP34: 0.6161462 | AQ34: 0.59383162 | AR34: 0.40465235 | AS34: 0.4143322 | AT34: 0.34144054 | AU34: 0.29700008 | AV34: 0.31532803 | AW34: 0.34812456 | AX34: 0.43572154 | AY34: 0.50506041 | AZ34: 0.58480194 | BA34: 0.66272936 | BB34: 0.64811807 | BC34: 0.78917368 | BD34: 0.88067365 | BE34: 0.82214424 | BF34: 0.78905662 | BG34: 0.77060691 | BH34: 0.59779727 | BI34: 0.61096833 | BJ34: 0.683576 | BK34: 0.60924372 | BL34: 0.57782585 | BM34: 0.4646746 | BN34: 0.47335413 | BO34: 0.5002162 | BP34: =_xlfn.XLOOKUP(B34,Countries_WB!$C$2:$C$219,Countries_WB!$D$2:$D$219,"No Data",0) -> Latin America & Caribbean | BQ34: =_xlfn.XLOOKUP(B34,Countries_WB!$C$2:$C$219,Countries_WB!$E$2:$E$219,"No Data",0) -> Upper middle income
A35: Barbados | B35: BRB | C35: Price level ratio of PPP conversion factor (GDP) to market exchange rate | D35: PA.NUS.PPPC.RF | AI35: 0.80562934 | AJ35: 0.81430675 | AK35: 0.81765441 | AL35: 0.83549796 | AM35: 0.83610673 | AN35: 0.82725608 | AO35: 0.83300326 | AP35: 0.82639052 | AQ35: 0.88831513 | AR35: 0.91480615 | AS35: 0.88769389 | AT35: 0.88771504 | AU35: 0.88202754 | AV35: 0.87460858 | AW35: 0.90138517 | AX35: 0.93225323 | AY35: 0.94164465 | AZ35: 0.99542274 | BA35: 0.99345542 | BB35: 0.97001342 | BC35: 0.99519849 | BD35: 1.0094435 | BE35: 1.0613686 | BF35: 1.0728049 | BG35: 1.0865591 | BH35: 1.0653898 | BI35: 1.0594341 | BJ35: 1.1015025 | BK35: 1.1107395 | BL35: 1.1374586 | BM35: 1.1416095 | BN35: 1.1439702 | BO35: 1.1114023 | BP35: =_xlfn.XLOOKUP(B35,Countries_WB!$C$2:$C$219,Countries_WB!$D$2:$D$219,"No Data",0) -> Latin America & Caribbean | BQ35: =_xlfn.XLOOKUP(B35,Countries_WB!$C$2:$C$219,Countries_WB!$E$2:$E$219,"No Data",0) -> High income
A36: Brunei Darussalam | B36: BRN | C36: Price level ratio of PPP conversion factor (GDP) to market exchange rate | D36: PA.NUS.PPPC.RF | AI36: 0.24363051 | AJ36: 0.24023856 | AK36: 0.25340236 | AL36: 0.24218793 | AM36: 0.22885689 | AN36: 0.24850399 | AO36: 0.25631621 | AP36: 0.25982569 | AQ36: 0.2013967 | AR36: 0.21883113 | AS36: 0.27142703 | AT36: 0.24112575 | AU36: 0.23846492 | AV36: 0.25501922 | AW36: 0.29665282 | AX36: 0.34691302 | AY36: 0.38793152 | AZ36: 0.40269465 | BA36: 0.47352484 | BB36: 0.35714126 | BC36: 0.43929413 | BD36: 0.56061652 | BE36: 0.54099722 | BF36: 0.53398819 | BG36: 0.51276784 | BH36: 0.4982967 | BI36: 0.48239466 | BJ36: 0.46843207 | BK36: 0.51143294 | BL36: 0.48022141 | BM36: 0.41779555 | BN36: 0.47400185 | BO36: 0.53612677 | BP36: =_xlfn.XLOOKUP(B36,Countries_WB!$C$2:$C$219,Countries_WB!$D$2:$D$219,"No Data",0) -> East Asia & Pacific | BQ36: =_xlfn.XLOOKUP(B36,Countries_WB!$C$2:$C$219,Countries_WB!$E$2:$E$219,"No Data",0) -> High income
A37: Bhutan | B37: BTN | C37: Price level ratio of PPP conversion factor (GDP) to market exchange rate | D37: PA.NUS.PPPC.RF | AI37: 0.3480108 | AJ37: 0.28224695 | AK37: 0.26375334 | AL37: 0.23763257 | AM37: 0.25404276 | AN37: 0.26068654 | AO37: 0.25328703 | AP37: 0.27431689 | AQ37: 0.26428208 | AR37: 0.26514762 | AS37: 0.26664936 | AT37: 0.26167788 | AU37: 0.26200814 | AV37: 0.27633853 | AW37: 0.28688673 | AX37: 0.30270944 | AY37: 0.30131686 | AZ37: 0.33096986 | BA37: 0.32565107 | BB37: 0.30465354 | BC37: 0.33733218 | BD37: 0.35133149 | BE37: 0.32089251 | BF37: 0.30948924 | BG37: 0.30603342 | BH37: 0.2897305 | BI37: 0.28024346 | BJ37: 0.29496125 | BK37: 0.27742974 | BL37: 0.27290695 | BM37: 0.26955216 | BN37: 0.27824149 | BO37: =BN37 -> 0.27824149 | BP37: =_xlfn.XLOOKUP(B37,Countries_WB!$C$2:$C$219,Countries_WB!$D$2:$D$219,"No Data",0) -> South Asia | BQ37: =_xlfn.XLOOKUP(B37,Countries_WB!$C$2:$C$219,Countries_WB!$E$2:$E$219,"No Data",0) -> Lower middle income
A38: Botswana | B38: BWA | C38: Price level ratio of PPP conversion factor (GDP) to market exchange rate | D38: PA.NUS.PPPC.RF | AI38: 0.46543655 | AJ38: 0.43578875 | AK38: 0.4353788 | AL38: 0.41867705 | AM38: 0.40499839 | AN38: 0.41163811 | AO38: 0.3914285 | AP38: 0.36785846 | AQ38: 0.34558099 | AR38: 0.35574153 | AS38: 0.35999162 | AT38: 0.33305639 | AU38: 0.30632155 | AV38: 0.39652798 | AW38: 0.44836128 | AX38: 0.46041079 | AY38: 0.4212564 | AZ38: 0.41304586 | BA38: 0.39858352 | BB38: 0.43496693 | BC38: 0.48745229 | BD38: 0.5344448 | BE38: 0.51878462 | BF38: 0.49123639 | BG38: 0.47731617 | BH38: 0.43737079 | BI38: 0.4196854 | BJ38: 0.45749095 | BK38: 0.45346785 | BL38: 0.42459723 | BM38: 0.41073622 | BN38: 0.44007143 | BO38: 0.4222009 | BP38: =_xlfn.XLOOKUP(B38,Countries_WB!$C$2:$C$219,Countries_WB!$D$2:$D$219,"No Data",0) -> Sub-Saharan Africa | BQ38: =_xlfn.XLOOKUP(B38,Countries_WB!$C$2:$C$219,Countries_WB!$E$2:$E$219,"No Data",0) -> Upper middle income
A39: Central African Republic | B39: CAF | C39: Price level ratio of PPP conversion factor (GDP) to market exchange rate | D39: PA.NUS.PPPC.RF | AI39: 0.80868688 | AJ39: 0.75200022 | AK39: 0.80542463 | AL39: 0.71020551 | AM39: 0.44121943 | AN39: 0.52826908 | AO39: 0.48825693 | AP39: 0.42413846 | AQ39: 0.41323285 | AR39: 0.40639869 | AS39: 0.37381961 | AT39: 0.35601697 | AU39: 0.36132349 | AV39: 0.42953919 | AW39: 0.43957956 | AX39: 0.44413305 | AY39: 0.44932191 | AZ39: 0.48630474 | BA39: 0.54830571 | BB39: 0.52034769 | BC39: 0.50928928 | BD39: 0.54485327 | BE39: 0.51341836 | BF39: 0.51497742 | BG39: 0.5892474 | BH39: 0.47956382 | BI39: 0.47257026 | BJ39: 0.4939737 | BK39: 0.49809806 | BL39: 0.47467603 | BM39: 0.48642114 | BN39: 0.49857507 | BO39: 0.43879757 | BP39: =_xlfn.XLOOKUP(B39,Countries_WB!$C$2:$C$219,Countries_WB!$D$2:$D$219,"No Data",0) -> Sub-Saharan Africa | BQ39: =_xlfn.XLOOKUP(B39,Countries_WB!$C$2:$C$219,Countries_WB!$E$2:$E$219,"No Data",0) -> Low income
A40: Canada | B40: CAN | C40: Price level ratio of PPP conversion factor (GDP) to market exchange rate | D40: PA.NUS.PPPC.RF | AI40: 1.0640692 | AJ40: 1.0802042 | AK40: 1.0157144 | AL40: 0.94154639 | AM40: 0.88356693 | AN40: 0.88052244 | AO40: 0.88552255 | AP40: 0.86708436 | AQ40: 0.79881631 | AR40: 0.80151444 | AS40: 0.82661033 | AT40: 0.7880062 | AU40: 0.78336392 | AV40: 0.87482264 | AW40: 0.94747271 | AX40: 1.0015217 | AY40: 1.0625573 | AZ40: 1.1284787 | BA40: 1.1568791 | BB40: 1.05174 | BC40: 1.1861032 | BD40: 1.2533675 | BE40: 1.2453981 | BF40: 1.1881911 | BG40: 1.113701 | BH40: 0.97595829 | BI40: 0.91055461 | BJ40: 0.93402459 | BK40: 0.93110755 | BL40: 0.93060233 | BM40: 0.91791265 | BN40: 0.98746216 | BO40: 0.94121433 | BP40: =_xlfn.XLOOKUP(B40,Countries_WB!$C$2:$C$219,Countries_WB!$D$2:$D$219,"No Data",0) -> North America | BQ40: =_xlfn.XLOOKUP(B40,Countries_WB!$C$2:$C$219,Countries_WB!$E$2:$E$219,"No Data",0) -> High income
...

Sheet Countries_WB
A1: Country | B1: Economy | C1: Code | D1: Region | E1: Income group | F1: Country code | G1: Country Currency
B2: Aruba | C2: ABW | D2: Latin America & Caribbean | E2: High income | F2: =C2 -> ABW | H2: 1
B3: Afghanistan | C3: AFG | D3: South Asia | E3: Low income | F3: =C3 -> AFG | H3: 2
B4: Angola | C4: AGO | D4: Sub-Saharan Africa | E4: Lower middle income | F4: =C4 -> AGO | H4: 3
B5: Albania | C5: ALB | D5: Europe & Central Asia | E5: Upper middle income | F5: =C5 -> ALB | H5: 4
B6: Andorra | C6: AND | D6: Europe & Central Asia | E6: High income | F6: =C6 -> AND | H6: 5
B7: United Arab Emirates | C7: ARE | D7: Middle East & North Africa | E7: High income | F7: =C7 -> ARE | H7: 6
B8: Argentina | C8: ARG | D8: Latin America & Caribbean | E8: Upper middle income | F8: =C8 -> ARG | H8: 7
B9: Armenia | C9: ARM | D9: Europe & Central Asia | E9: Upper middle income | F9: =C9 -> ARM | H9: 8
B10: American Samoa | C10: ASM | D10: East Asia & Pacific | E10: High income | F10: =C10 -> ASM | H10: 9
B11: Antigua and Barbuda | C11: ATG | D11: Latin America & Caribbean | E11: High income | F11: =C11 -> ATG | H11: 10
B12: Australia | C12: AUS | D12: East Asia & Pacific | E12: High income | F12: =C12 -> AUS | H12: 11
B13: Austria | C13: AUT | D13: Europe & Central Asia | E13: High income | F13: =C13 -> AUT | H13: 12
... B21: Bahrain | C21: BHR | D21: Middle East & North Africa | E21: High income | F21: =C21 -> BHR | H21: 20
A22: Bahamas | B22: Bahamas, The | C22: BHS | D22: Latin America & Caribbean | E22: High income | F22: =C22 -> BHS | H22: 21
B23: Bosnia and Herzegovina | C23: BIH | D23: Europe & Central Asia | E23: Upper middle income | F23: =C23 -> BIH | H23: 22
B24: Belarus | C24: BLR | D24: Europe & Central Asia | E24: Upper middle income | F24: =C24 -> BLR | H24: 23
B25: Belize | C25: BLZ | D25: Latin America & Caribbean | E25: Upper middle income | F25: =C25 -> BLZ | H25: 24
B26: Bermuda | C26: BMU | D26: North America | E26: High income | F26: =C26 -> BMU | H26: 25
A27: Bolivia (Plurinational State of) | B27: Bolivia | C27: BOL | D27: Latin America & Caribbean | E27: Lower middle income | F27: =C27 -> BOL | H27: 26
B28: Brazil | C28: BRA | D28: Latin America & Caribbean | E28: Upper middle income | F28: =C28 -> BRA | H28: 27
B29: Barbados | C29: BRB | D29: Latin America & Caribbean | E29: High income | F29: =C29 -> BRB | H29: 28
B30: Brunei Darussalam | C30: BRN | D30: East Asia & Pacific | E30: High income | F30: =C30 -> BRN | H30: 29
B31: Bhutan | C31: BTN | D31: South Asia | E31: Lower middle income | F31: =C31 -> BTN | H31: 30
B32: Botswana | C32: BWA | D32: Sub-Saharan Africa | E32: Upper middle income | F32: =C32 -> BWA | H32: 31
B33: Central African Republic | C33: CAF | D33: Sub-Saharan Africa | E33: Low income | F33: =C33 -> CAF | H33: 32
B34: Canada | C34: CAN | D34: North America | E34: High income | F34: =C34 -> CAN | H34: 33
B35: Switzerland | C35: CHE | D35: Europe & Central Asia | E35: High income | F35: =C35 -> CHE | H35: 34
A36: Jersey | B36: Channel Islands | C36: CHI | D36: Europe & Central Asia | E36: High income | F36: =C36 -> CHI | H36: 35
B37: Chile | C37: CHL | D37: Latin America & Caribbean | E37: High income | F37: =C37 -> CHL | H37: 36
B38: China | C38: CHN | D38: East Asia & Pacific | E38: Upper middle income | F38: =C38 -> CHN | H38: 37
A39: Ivory Coast | B39: Côte d’Ivoire | C39: CIV | D39: Sub-Saharan Africa | E39: Lower middle income | F39: =C39 -> CIV | H39: 38
B40: Cameroon | C40: CMR | D40: Sub-Saharan Africa | E40: Lower middle income | F40: =C40 -> CMR | H40: 39
B41: Congo, Dem. Rep. | C41: COD | D41: Sub-Saharan Africa | E41: Low income | F41: =C41 -> COD | H41: 40
B42: Congo, Rep. | C42: COG | D42: Sub-Saharan Africa | E42: Lower middle income | F42: =C42 -> COG | H42: 41
B43: Colombia | C43: COL | D43: Latin America & Caribbean | E43: Upper middle income | F43: =C43 -> COL | H43: 42
B44: Comoros | C44: COM | D44: Sub-Saharan Africa | E44: Lower middle income | F44: =C44 -> COM | H44: 43
B45: Cabo Verde | C45: CPV | D45: Sub-Saharan Africa | E45: Lower middle income | F45: =C45 -> CPV | H45: 44
B46: Costa Rica | C46: CRI | D46: Latin America & Caribbean | E46: Upper middle income | F46: =C46 -> CRI | H46: 45
B47: Cuba | C47: CUB | D47: Latin America & Caribbean | E47: Upper middle income | F47: =C47 -> CUB | H47: 46
...

Sheet Unemployment_WB
A1: Data Source | B1: World Development Indicators
A2: Last Updated Date | B2: 45343
A3: Vlookup | B3: 1 | C3: 2 | D3: 3 | E3: 4 | F3: 5 | G3: 6 | H3: 7 | I3: 8 | J3: 9 | K3: 10 | L3: 11 | M3: 12 | N3: 13 | O3: 14 | P3: 15 | Q3: 16 | R3: 17 | S3: 18 | T3: 19 | U3: 20 | V3: 21 | W3: 22 | X3: 23 | Y3: 24 | Z3: 25 | AA3: 26 | AB3: 27 | AC3: 28 | AD3: 29 | AE3: 30 | AF3: 31 | AG3: 32 | AH3: 33 | AI3: 34 | AJ3: 35 | AK3: 36 | AL3: 37 | AM3: 38 | AN3: 39 | AO3: 40 | AP3: 41 | AQ3: 42 | AR3: 43 | AS3: 44 | AT3: 45 | AU3: 46 | AV3: 47 | AW3: 48 | AX3: 49 | AY3: 50 | AZ3: 51 | BA3: 52 | BB3: 53 | BC3: 54 | BD3: 55 | BE3: 56 | BF3: 57 | BG3: 58 | BH3: 59 | BI3: 60 | BJ3: 61 | BK3: 62 | BL3: 63 | BM3: 64 | BN3: 65 | BO3: 65
A4: Country Name | B4: Country Code | C4: Indicator Name | D4: Indicator Code | E4: 1960 | F4: 1961 | G4: 1962 | H4: 1963 | I4: 1964 | J4: 1965 | K4: 1966 | L4: 1967 | M4: 1968 | N4: 1969 | O4: 1970 | P4: 1971 | Q4: 1972 | R4: 1973 | S4: 1974 | T4: 1975 | U4: 1976 | V4: 1977 | W4: 1978 | X4: 1979 | Y4: 1980 | Z4: 1981 | AA4: 1982 | AB4: 1983 | AC4: 1984 | AD4: 1985 | AE4: 1986 | AF4: 1987 | AG4: 1988 | AH4: 1989 | AI4: 1990 | AJ4: 1991 | AK4: 1992 | AL4: 1993 | AM4: 1994 | AN4: 1995 | AO4: 1996 | AP4: 1997 | AQ4: 1998 | AR4: 1999 | AS4: 2000 | AT4: 2001 | AU4: 2002 | AV4: 2003 | AW4: 2004 | AX4: 2005 | AY4: 2006 | AZ4: 2007 | BA4: 2008 | BB4: 2009 | BC4: 2010 | BD4: 2011 | BE4: 2012 | BF4: 2013 | BG4: 2014 | BH4: 2015 | BI4: 2016 | BJ4: 2017 | BK4: 2018 | BL4: 2019 | BM4: 2020 | BN4: 2021 | BO4: 2022
A5: Aruba | B5: ABW | C5: Unemployment, total (% of total labor force) (modeled ILO estimate) | D5: SL.UEM.TOTL.ZS
A6: Africa Eastern and Southern | B6: AFE | C6: Unemployment, total (% of total labor force) (modeled ILO estimate) | D6: SL.UEM.TOTL.ZS | AJ6: 7.8379511 | AK6: 7.9917248 | AL6: 7.9803818 | AM6: 7.8413725 | AN6: 7.5621295 | AO6: 7.4444711 | AP6: 7.3856467 | AQ6: 7.444838 | AR6: 7.516038 | AS6: 7.4709109 | AT6: 7.3471513 | AU6: 7.3080999 | AV6: 7.2648985 | AW6: 7.0632701 | AX6: 6.878497 | AY6: 6.8023942 | AZ6: 6.7462657 | BA6: 6.7367981 | BB6: 6.8592944 | BC6: 7.2753639 | BD6: 7.1493012 | BE6: 6.9848944 | BF6: 6.904383 | BG6: 6.8845004 | BH6: 6.9830641 | BI6: 7.1521569 | BJ6: 7.2742983 | BK6: 7.2375626 | BL6: 7.4267768 | BM6: 7.9102905 | BN6: 8.303939 | BO6: 7.7481444
